Workbook

Sheet Leyenda
A1: Gestión de pruebas – HU-004 Registro de mermas justificadas
A2: Sistema web de control de inventario – Representaciones Martín S.A.C. · Sprint 1 · PC 9 y PC 10
A4: Hoja | B4: Contenido
A5: Casos de Prueba | B5: PC 9: catálogo de casos con prioridad, datos de prueba, pasos, resultado esperado y criterio de aceptación de HU-004.
A6: Ejecución | B6: PC 10: cada ejecución real (ciclo 1 y ciclo 2) con fecha, herramienta, resultado obtenido, estado, defecto asociado y ruta de la evidencia en el repositorio.
A7: Defectos | B7: PC 10: defectos detectados, con severidad, prioridad, caso que los detectó, corrección (commit) y estado.
A8: Resumen | B8: Indicadores calculados con fórmulas a partir de las otras hojas (se actualizan solos al editar).
A10: Celdas amarillas | B10: Campos editables por el equipo: Responsable (propuesto) en Ejecución y Responsable en Defectos. El resto proviene de las evidencias reales y no debe modificarse.
A11: Prioridad | B11: Alta = bloquea el criterio de aceptación o la seguridad · Media = afecta una regla de negocio secundaria · Baja = estética o de bajo impacto.
A12: Severidad (defectos) | B12: Alta = pérdida de datos, seguridad o funcionalidad principal · Media = regla de negocio incorrecta con alternativa · Baja = impacto menor.
A13: Estado (ejecución) | B13: Aprobado · Fallido · Bloqueado.
A14: Estado (defectos) | B14: Abierto · Corregido · Cerrado (corregido y verificado) · Diferido (fuera del alcance del Sprint 1).
A15: Ciclo | B15: Ciclo 1 = primera ejecución · Ciclo 2 = re-ejecución tras corregir los defectos (regresión) · Ciclo 3 = verificación de DEF-10 tras habilitar TCP/IP (25/10/2026).
A17: Criterios de aceptación | B17: CA-1 y CA-2 provienen de la HU-004 del informe. CA-3, CA-4 y CA-5 se añadieron en el refinamiento del Sprint 1.
... A26: Generado | B26: Desde las evidencias en pruebas/evidencias/ el 2026-10-24 19:33 (hora de Lima).

Sheet Casos de Prueba
A1: PC 9 – Casos de prueba de la HU-004 (y regresión de modelos)
A2: Fuente: tests/e2e, tests/api y tests/unit del repositorio. Prioridad según la leyenda.
A3: ID | B3: ID en el script | C3: Título | D3: Tipo | E3: Técnica de diseño | F3: Prioridad | G3: Criterio de aceptación | H3: Precondiciones | I3: Datos de prueba | J3: Pasos | K3: Resultado esperado | L3: Automatización
A4: CP-HU4-01 | B4: CPF-01 | C4: Registrar una merma justificada (flujo principal) | D4: Funcional E2E | E4: Flujo principal (caso de uso) | F4: Alta | G4: CA-1, CA-5 | H4: Ambiente de pruebas: npm run db:pruebas:reset, npm run server:pruebas y npm run dev. Usuario almacen@rep-martin.com con la contraseña de prueba. | I4: Producto MEL-VES-ROB-18; tipo MERMA_DANO; cantidad 2; motivo predefinido; justificación "Prueba automatizada: esquina desportillada por montacargas en el rack A-P01-R01" | J4: 1. Iniciar sesión. 2. Abrir "Ajustes y Mermas". 3. Pulsar "Registrar Ajuste o Merma". 4. Completar el formulario. 5. Pulsar "Asentar Ajuste en Inventario". | K4: Mensaje "Ajuste AJU-AAAA-NNNNN registrado. Stock: N → N-2" y nueva fila en el historial con el folio y el SKU. | L4: Selenium: tests/e2e/ajustes.e2e.js
A5: CP-HU4-02 | B5: CPF-02 | C5: Rechazar una justificación técnica demasiado corta | D5: Funcional E2E | E5: Partición de equivalencia (inválida) | F5: Alta | G5: CA-1 | H5: Ambiente de pruebas: npm run db:pruebas:reset, npm run server:pruebas y npm run dev. Usuario almacen@rep-martin.com con la contraseña de prueba. | I5: Justificación "roto" (4 caracteres) | J5: 1. Abrir el formulario. 2. Escribir la justificación corta. 3. Pulsar "Asentar". | K5: Mensaje "La justificación técnica debe tener al menos 10 caracteres." y ningún ajuste nuevo. | L5: Selenium: tests/e2e/ajustes.e2e.js
A6: CP-HU4-03 | B6: CPF-03 | C6: Impedir descontar más que el stock disponible | D6: Funcional E2E | E6: Valor límite | F6: Alta | G6: CA-3 | H6: Ambiente de pruebas: npm run db:pruebas:reset, npm run server:pruebas y npm run dev. Usuario almacen@rep-martin.com con la contraseña de prueba. | I6: Producto HER-BIS-CAN-35 (stock 1); cantidad 2 | J6: 1. Abrir el formulario. 2. Elegir el producto y cantidad 2. 3. Pulsar "Asentar". | K6: Mensaje "No se puede descontar más del stock actual (1 unid.)." sin registrar el ajuste. | L6: Selenium: tests/e2e/ajustes.e2e.js
A7: CP-HU4-04 | B7: API-01 | C7: Merma válida registrada por Encargado de Almacén | D7: API | E7: Partición de equivalencia (válida) | F7: Alta | G7: CA-1, CA-5 | H7: npm run db:pruebas:reset y npm run server:pruebas. | I7: POST /api/ajustes {productoId MEL-VES-ROB-18, MERMA_DANO, 2, motivo, justificación} | J7: Enviar la petición con el token de almacen@rep-martin.com y consultar el stock. | K7: HTTP 201 y stock disminuye en 2. | L7: npm run test:api
A8: CP-HU4-05 | B8: API-02 | C8: Dos mermas seguidas del mismo producto generan folios distintos | D8: API | E8: Prueba de regresión (DEF-01) | F8: Media | G8: CA-5 | H8: npm run db:pruebas:reset y npm run server:pruebas. | I8: Misma petición de CP-HU4-04 enviada dos veces en el mismo minuto | J8: Enviar dos peticiones consecutivas. | K8: Ambas HTTP 201 con folios AJU distintos. | L8: npm run test:api
A9: CP-HU4-06 | B9: API-03 | C9: Justificación técnica vacía | D9: API | E9: Partición de equivalencia (inválida) | F9: Alta | G9: CA-1 | H9: npm run db:pruebas:reset y npm run server:pruebas. | I9: detalle = " " | J9: Enviar la petición. | K9: HTTP 400 "La justificación técnica es obligatoria." | L9: npm run test:api
A10: CP-HU4-07 | B10: API-04 | C10: Justificación de menos de 10 caracteres | D10: API | E10: Valor límite | F10: Media | G10: CA-1 | H10: npm run db:pruebas:reset y npm run server:pruebas. | I10: detalle = "roto" | J10: Enviar la petición. | K10: HTTP 400 "...al menos 10 caracteres." | L10: npm run test:api
A11: CP-HU4-08 | B11: API-05 | C11: Cantidad 0 | D11: API | E11: Valor límite | F11: Media | G11: CA-3 | H11: npm run db:pruebas:reset y npm run server:pruebas. | I11: cantidad = 0 | J11: Enviar la petición. | K11: HTTP 400 "La cantidad del ajuste debe ser un número entero mayor a 0." | L11: npm run test:api
A12: CP-HU4-09 | B12: API-06 | C12: Descontar más que el stock disponible | D12: API | E12: Valor límite | F12: Alta | G12: CA-3 | H12: npm run db:pruebas:reset y npm run server:pruebas. | I12: Producto HER-BIS-CAN-35 (stock 1); cantidad 2 | J12: Enviar la petición. | K12: HTTP 400 "No se puede descontar más del stock actual (1 unid.)." | L12: npm run test:api
A13: CP-HU4-10 | B13: API-07 | C13: Ajuste sobre un producto dado de baja | D13: API | E13: Partición de equivalencia (inválida) | F13: Media | G13: CA-3 | H13: npm run db:pruebas:reset y npm run server:pruebas. | I13: Producto HER-PEG-EXT-01 (Activo = 0) | J13: Enviar la petición. | K13: HTTP 400 "El producto especificado no existe o está inactivo." | L13: npm run test:api
A14: CP-HU4-11 | B14: API-08 | C14: Rol Gerencia intenta registrar un ajuste | D14: API | E14: Control de acceso (RBAC) | F14: Alta | G14: CA-4 | H14: npm run db:pruebas:reset y npm run server:pruebas. | I14: Token de gerencia@rep-martin.com | J14: Enviar la petición. | K14: HTTP 403 "No tiene permisos para esta acción." | L14: npm run test:api
... A25: CP-UT-06 | B25: seguridad.test.js | C25: Contraseñas bcrypt, tokens y folios aleatorios | D25: Unitaria | E25: Propiedades de seguridad | F25: Media | G25: — (RF-01, RF-02) | H25: npm install. No requiere base de datos ni navegador. | I25: 200 contraseñas temporales, 20 000 dígitos aleatorios | J25: npm test | K25: Todas las pruebas del archivo pasan. | L25: Vitest

Sheet Ejecución
A1: PC 10 – Registro de ejecución de los casos
A2: Cada fila corresponde a una ejecución real; la evidencia es la ruta del archivo en el repositorio. Fechas en hora de Lima.
A3: ID ejecución | B3: ID caso | C3: Ciclo | D3: Fecha y hora | E3: Herramienta | F3: Responsable (propuesto) | G3: Ambiente | H3: Resultado obtenido | I3: Estado | J3: Defecto asociado | K3: Evidencia
A4: EJ-001 | B4: CP-UT-01 | C4: 1 | D4: 2026-10-23 23:57 | E4: Vitest 3 | F4: Alvaro Mendoza (QA) | G4: Local: RepresentacionesMartinDB_Pruebas + Edge | H4: 45/45 pruebas correctas | I4: Aprobado | K4: pruebas/evidencias/pc07/vitest-ejecucion-1.json
A5: EJ-002 | B5: CP-UT-02 | C5: 1 | D5: 2026-10-23 23:57 | E5: Vitest 3 | F5: Alvaro Mendoza (QA) | G5: Local: RepresentacionesMartinDB_Pruebas + Edge | H5: 15/15 pruebas correctas | I5: Aprobado | K5: pruebas/evidencias/pc07/vitest-ejecucion-1.json
A6: EJ-003 | B6: CP-UT-03 | C6: 1 | D6: 2026-10-23 23:57 | E6: Vitest 3 | F6: Alvaro Mendoza (QA) | G6: Local: RepresentacionesMartinDB_Pruebas + Edge | H6: 13/15 pruebas correctas. Fallan: rechaza una cantidad decimal; rechaza un tipo de movimiento desconocido | I6: Fallido | J6: DEF-05, DEF-06 | K6: pruebas/evidencias/pc07/vitest-ejecucion-1.json
A7: EJ-004 | B7: CP-UT-04 | C7: 1 | D7: 2026-10-23 23:57 | E7: Vitest 3 | F7: Alvaro Mendoza (QA) | G7: Local: RepresentacionesMartinDB_Pruebas + Edge | H7: 15/19 pruebas correctas. Fallan: rechaza precioVenta no numérico (abc); rechaza costoCompra no numérico (abc); rechaza stockMinimo no numérico (diez); rechaza stockMaximo no numérico (undefined) | I7: Fallido | J7: DEF-04 | K7: pruebas/evidencias/pc07/vitest-ejecucion-1.json
A8: EJ-005 | B8: CP-UT-05 | C8: 1 | D8: 2026-10-23 23:57 | E8: Vitest 3 | F8: Alvaro Mendoza (QA) | G8: Local: RepresentacionesMartinDB_Pruebas + Edge | H8: 3/4 pruebas correctas. Fallan: redondea el subtotal a céntimos | I8: Fallido | J8: DEF-07 | K8: pruebas/evidencias/pc07/vitest-ejecucion-1.json
A9: EJ-006 | B9: CP-UT-06 | C9: 1 | D9: 2026-10-23 23:57 | E9: Vitest 3 | F9: Alvaro Mendoza (QA) | G9: Local: RepresentacionesMartinDB_Pruebas + Edge | H9: 8/8 pruebas correctas | I9: Aprobado | K9: pruebas/evidencias/pc07/vitest-ejecucion-1.json
A10: EJ-007 | B10: CP-UT-01 | C10: 2 | D10: 2026-10-23 23:58 | E10: Vitest 3 + cobertura v8 | F10: Alvaro Mendoza (QA) | G10: Local: RepresentacionesMartinDB_Pruebas + Edge | H10: 45/45 pruebas correctas | I10: Aprobado | K10: pruebas/evidencias/pc07/vitest-ejecucion-2-cobertura.txt
A11: EJ-008 | B11: CP-UT-02 | C11: 2 | D11: 2026-10-23 23:58 | E11: Vitest 3 + cobertura v8 | F11: Alvaro Mendoza (QA) | G11: Local: RepresentacionesMartinDB_Pruebas + Edge | H11: 15/15 pruebas correctas | I11: Aprobado | K11: pruebas/evidencias/pc07/vitest-ejecucion-2-cobertura.txt
A12: EJ-009 | B12: CP-UT-03 | C12: 2 | D12: 2026-10-23 23:58 | E12: Vitest 3 + cobertura v8 | F12: Alvaro Mendoza (QA) | G12: Local: RepresentacionesMartinDB_Pruebas + Edge | H12: 15/15 pruebas correctas | I12: Aprobado | J12: DEF-05, DEF-06 | K12: pruebas/evidencias/pc07/vitest-ejecucion-2-cobertura.txt
A13: EJ-010 | B13: CP-UT-04 | C13: 2 | D13: 2026-10-23 23:58 | E13: Vitest 3 + cobertura v8 | F13: Alvaro Mendoza (QA) | G13: Local: RepresentacionesMartinDB_Pruebas + Edge | H13: 19/19 pruebas correctas | I13: Aprobado | J13: DEF-04 | K13: pruebas/evidencias/pc07/vitest-ejecucion-2-cobertura.txt
A14: EJ-011 | B14: CP-UT-05 | C14: 2 | D14: 2026-10-23 23:58 | E14: Vitest 3 + cobertura v8 | F14: Alvaro Mendoza (QA) | G14: Local: RepresentacionesMartinDB_Pruebas + Edge | H14: 4/4 pruebas correctas | I14: Aprobado | J14: DEF-07 | K14: pruebas/evidencias/pc07/vitest-ejecucion-2-cobertura.txt
A15: EJ-012 | B15: CP-UT-06 | C15: 2 | D15: 2026-10-23 23:58 | E15: Vitest 3 + cobertura v8 | F15: Alvaro Mendoza (QA) | G15: Local: RepresentacionesMartinDB_Pruebas + Edge | H15: 8/8 pruebas correctas | I15: Aprobado | K15: pruebas/evidencias/pc07/vitest-ejecucion-2-cobertura.txt
A16: EJ-013 | B16: CP-HU4-01 | C16: 1 | D16: 2026-10-24 00:01 | E16: Selenium WebDriver 4.51.0 + MicrosoftEdge 156.0.4314.42 | F16: Alvaro Mendoza (QA) | G16: Local: RepresentacionesMartinDB_Pruebas + Edge | H16: AJU-2026-00002 registrado; stock 95 → 93; historial 1 → 2 filas Observación: la captura muestra la fecha con -5 h (DEF-08). | I16: Aprobado | J16: DEF-08 | K16: pruebas/evidencias/pc08/2026-10-24T05-00-53/01-login.png pruebas/evidencias/pc08/2026-10-24T05-00-53/02-modulo-ajustes.png pruebas/evidencias/pc08/2026-10-24T05-00-53/03-formulario-merma.png pruebas/evidencias/pc08/2026-10-24T05-00-53/04-merma-registrada.png
A17: EJ-014 | B17: CP-HU4-02 | C17: 1 | D17: 2026-10-24 00:01 | E17: Selenium WebDriver 4.51.0 + MicrosoftEdge 156.0.4314.42 | F17: Alvaro Mendoza (QA) | G17: Local: RepresentacionesMartinDB_Pruebas + Edge | H17: Mensaje mostrado: "La justificación técnica debe tener al menos 10 caracteres." | I17: Aprobado | K17: pruebas/evidencias/pc08/2026-10-24T05-00-53/05-error-justificacion-corta.png
A18: EJ-015 | B18: CP-HU4-03 | C18: 1 | D18: 2026-10-24 00:01 | E18: Selenium WebDriver 4.51.0 + MicrosoftEdge 156.0.4314.42 | F18: Alvaro Mendoza (QA) | G18: Local: RepresentacionesMartinDB_Pruebas + Edge | H18: Stock 1, solicitado 2: "No se puede descontar más del stock actual (1 unid.)." | I18: Aprobado | K18: pruebas/evidencias/pc08/2026-10-24T05-00-53/06-error-stock-insuficiente.png
A19: EJ-016 | B19: CP-HU4-01 | C19: 2 | D19: 2026-10-24 00:02 | E19: Selenium WebDriver 4.51.0 + MicrosoftEdge 156.0.4314.42 | F19: Alvaro Mendoza (QA) | G19: Local: RepresentacionesMartinDB_Pruebas + Edge | H19: AJU-2026-00002 registrado; stock 95 → 93; historial 1 → 2 filas | I19: Aprobado | J19: DEF-08 | K19: pruebas/evidencias/pc08/2026-10-24T05-02-31/01-login.png pruebas/evidencias/pc08/2026-10-24T05-02-31/02-modulo-ajustes.png pruebas/evidencias/pc08/2026-10-24T05-02-31/03-formulario-merma.png pruebas/evidencias/pc08/2026-10-24T05-02-31/04-merma-registrada.png
A20: EJ-017 | B20: CP-HU4-02 | C20: 2 | D20: 2026-10-24 00:02 | E20: Selenium WebDriver 4.51.0 + MicrosoftEdge 156.0.4314.42 | F20: Alvaro Mendoza (QA) | G20: Local: RepresentacionesMartinDB_Pruebas + Edge | H20: Mensaje mostrado: "La justificación técnica debe tener al menos 10 caracteres." | I20: Aprobado | K20: pruebas/evidencias/pc08/2026-10-24T05-02-31/05-error-justificacion-corta.png
A21: EJ-018 | B21: CP-HU4-03 | C21: 2 | D21: 2026-10-24 00:02 | E21: Selenium WebDriver 4.51.0 + MicrosoftEdge 156.0.4314.42 | F21: Alvaro Mendoza (QA) | G21: Local: RepresentacionesMartinDB_Pruebas + Edge | H21: Stock 1, solicitado 2: "No se puede descontar más del stock actual (1 unid.)." | I21: Aprobado | K21: pruebas/evidencias/pc08/2026-10-24T05-02-31/06-error-stock-insuficiente.png
A22: EJ-019 | B22: CP-HU4-01 | C22: 2 | D22: 2026-10-24 00:08 | E22: Selenium WebDriver 4.51.0 + MicrosoftEdge 156.0.4314.42 | F22: Alvaro Mendoza (QA) | G22: Local: RepresentacionesMartinDB_Pruebas + Edge | H22: AJU-2026-00005 registrado; stock 96 → 94; historial 4 → 5 filas | I22: Aprobado | K22: pruebas/evidencias/pc08/2026-10-24T05-08-29/01-login.png pruebas/evidencias/pc08/2026-10-24T05-08-29/02-modulo-ajustes.png pruebas/evidencias/pc08/2026-10-24T05-08-29/03-formulario-merma.png pruebas/evidencias/pc08/2026-10-24T05-08-29/04-merma-registrada.png
A23: EJ-020 | B23: CP-HU4-02 | C23: 2 | D23: 2026-10-24 00:08 | E23: Selenium WebDriver 4.51.0 + MicrosoftEdge 156.0.4314.42 | F23: Alvaro Mendoza (QA) | G23: Local: RepresentacionesMartinDB_Pruebas + Edge | H23: Mensaje mostrado: "La justificación técnica debe tener al menos 10 caracteres." | I23: Aprobado | K23: pruebas/evidencias/pc08/2026-10-24T05-08-29/05-error-justificacion-corta.png
A24: EJ-021 | B24: CP-HU4-03 | C24: 2 | D24: 2026-10-24 00:08 | E24: Selenium WebDriver 4.51.0 + MicrosoftEdge 156.0.4314.42 | F24: Alvaro Mendoza (QA) | G24: Local: RepresentacionesMartinDB_Pruebas + Edge | H24: Stock 1, solicitado 2: "No se puede descontar más del stock actual (1 unid.)." | I24: Aprobado | K24: pruebas/evidencias/pc08/2026-10-24T05-08-29/06-error-stock-insuficiente.png
A25: EJ-022 | B25: CP-HU4-01 | C25: 3 | D25: 2026-10-24 19:32 | E25: Selenium WebDriver 4.51.0 + MicrosoftEdge 156.0.4314.42 | F25: Alvaro Mendoza (QA) | G25: Local: RepresentacionesMartinDB_Pruebas + Edge | H25: AJU-2026-00005 registrado; stock 96 → 94; historial 4 → 5 filas Verificación de DEF-10: puerto 1433 y pool de 10 conexiones. | I25: Aprobado | J25: DEF-10 | K25: pruebas/evidencias/pc08/2026-10-25T00-32-11/01-login.png pruebas/evidencias/pc08/2026-10-25T00-32-11/02-modulo-ajustes.png pruebas/evidencias/pc08/2026-10-25T00-32-11/03-formulario-merma.png pruebas/evidencias/pc08/2026-10-25T00-32-11/04-merma-registrada.png
A26: EJ-023 | B26: CP-HU4-02 | C26: 3 | D26: 2026-10-24 19:32 | E26: Selenium WebDriver 4.51.0 + MicrosoftEdge 156.0.4314.42 | F26: Alvaro Mendoza (QA) | G26: Local: RepresentacionesMartinDB_Pruebas + Edge | H26: Mensaje mostrado: "La justificación técnica debe tener al menos 10 caracteres." Verificación de DEF-10: puerto 1433 y pool de 10 conexiones. | I26: Aprobado | J26: DEF-10 | K26: pruebas/evidencias/pc08/2026-10-25T00-32-11/05-error-justificacion-corta.png
A27: EJ-024 | B27: CP-HU4-03 | C27: 3 | D27: 2026-10-24 19:32 | E27: Selenium WebDriver 4.51.0 + MicrosoftEdge 156.0.4314.42 | F27: Alvaro Mendoza (QA) | G27: Local: RepresentacionesMartinDB_Pruebas + Edge | H27: Stock 1, solicitado 2: "No se puede descontar más del stock actual (1 unid.)." Verificación de DEF-10: puerto 1433 y pool de 10 conexiones. | I27: Aprobado | J27: DEF-10 | K27: pruebas/evidencias/pc08/2026-10-25T00-32-11/06-error-stock-insuficiente.png
A28: EJ-025 | B28: CP-HU4-04 | C28: 1 | D28: 2026-10-24 00:06 | E28: Node.js fetch (tests/api/ajustes.api.js) | F28: Alvaro Mendoza (QA) | G28: Local: RepresentacionesMartinDB_Pruebas + Edge | H28: 201; Ajuste AJU-2026-00002 registrado. Stock: 95 → 93.; stock 95 → 93 | I28: Aprobado | K28: pruebas/evidencias/pc10/api-2026-10-24T05-06-39.json
A29: EJ-026 | B29: CP-HU4-05 | C29: 1 | D29: 2026-10-24 00:06 | E29: Node.js fetch (tests/api/ajustes.api.js) | F29: Alvaro Mendoza (QA) | G29: Local: RepresentacionesMartinDB_Pruebas + Edge | H29: 201; folios AJU-2026-00002 y AJU-2026-00003 | I29: Aprobado | J29: DEF-01 | K29: pruebas/evidencias/pc10/api-2026-10-24T05-06-39.json
A30: EJ-027 | B30: CP-HU4-06 | C30: 1 | D30: 2026-10-24 00:06 | E30: Node.js fetch (tests/api/ajustes.api.js) | F30: Alvaro Mendoza (QA) | G30: Local: RepresentacionesMartinDB_Pruebas + Edge | H30: 400; La justificación técnica es obligatoria. | I30: Aprobado | K30: pruebas/evidencias/pc10/api-2026-10-24T05-06-39.json
A31: EJ-028 | B31: CP-HU4-07 | C31: 1 | D31: 2026-10-24 00:06 | E31: Node.js fetch (tests/api/ajustes.api.js) | F31: Alvaro Mendoza (QA) | G31: Local: RepresentacionesMartinDB_Pruebas + Edge | H31: 400; La justificación técnica debe tener al menos 10 caracteres. | I31: Aprobado | K31: pruebas/evidencias/pc10/api-2026-10-24T05-06-39.json
A32: EJ-029 | B32: CP-HU4-08 | C32: 1 | D32: 2026-10-24 00:06 | E32: Node.js fetch (tests/api/ajustes.api.js) | F32: Alvaro Mendoza (QA) | G32: Local: RepresentacionesMartinDB_Pruebas + Edge | H32: 400; La cantidad del ajuste debe ser un número entero mayor a 0. | I32: Aprobado | K32: pruebas/evidencias/pc10/api-2026-10-24T05-06-39.json
A33: EJ-030 | B33: CP-HU4-09 | C33: 1 | D33: 2026-10-24 00:06 | E33: Node.js fetch (tests/api/ajustes.api.js) | F33: Alvaro Mendoza (QA) | G33: Local: RepresentacionesMartinDB_Pruebas + Edge | H33: 400; No se puede descontar más del stock actual (1 unid.). | I33: Aprobado | K33: pruebas/evidencias/pc10/api-2026-10-24T05-06-39.json
A34: EJ-031 | B34: CP-HU4-10 | C34: 1 | D34: 2026-10-24 00:06 | E34: Node.js fetch (tests/api/ajustes.api.js) | F34: Alvaro Mendoza (QA) | G34: Local: RepresentacionesMartinDB_Pruebas + Edge | H34: 400; El producto especificado no existe o está inactivo. | I34: Aprobado | K34: pruebas/evidencias/pc10/api-2026-10-24T05-06-39.json
A35: EJ-032 | B35: CP-HU4-11 | C35: 1 | D35: 2026-10-24 00:06 | E35: Node.js fetch (tests/api/ajustes.api.js) | F35: Alvaro Mendoza (QA) | G35: Local: RepresentacionesMartinDB_Pruebas + Edge | H35: 403; No tiene permisos para esta acción. | I35: Aprobado | K35: pruebas/evidencias/pc10/api-2026-10-24T05-06-39.json
A36: EJ-033 | B36: CP-HU4-12 | C36: 1 | D36: 2026-10-24 00:06 | E36: Node.js fetch (tests/api/ajustes.api.js) | F36: Alvaro Mendoza (QA) | G36: Local: RepresentacionesMartinDB_Pruebas + Edge | H36: 401; Sesión no iniciada. | I36: Aprobado | K36: pruebas/evidencias/pc10/api-2026-10-24T05-06-39.json
A37: EJ-034 | B37: CP-HU4-13 | C37: 1 | D37: 2026-10-24 00:06 | E37: Node.js fetch (tests/api/ajustes.api.js) | F37: Alvaro Mendoza (QA) | G37: Local: RepresentacionesMartinDB_Pruebas + Edge | H37: 201; stock 91 → 96 | I37: Aprobado | K37: pruebas/evidencias/pc10/api-2026-10-24T05-06-39.json
A38: EJ-035 | B38: CP-HU4-14 | C38: 1 | D38: 2026-10-24 00:06 | E38: Node.js fetch (tests/api/ajustes.api.js) | F38: Alvaro Mendoza (QA) | G38: Local: RepresentacionesMartinDB_Pruebas + Edge | H38: 200; 4 ajustes; incluye AJU-2026-00002, AJU-2026-00003, AJU-2026-00004: true | I38: Aprobado | K38: pruebas/evidencias/pc10/api-2026-10-24T05-06-39.json
A39: EJ-036 | B39: CP-HU4-15 | C39: 1 | D39: 2026-10-24 00:06 | E39: Node.js fetch (tests/api/ajustes.api.js) | F39: Alvaro Mendoza (QA) | G39: Local: RepresentacionesMartinDB_Pruebas + Edge | H39: 3 asientos: AJU-2026-00002, AJU-2026-00003, AJU-2026-00004 | I39: Aprobado | K39: pruebas/evidencias/pc10/api-2026-10-24T05-06-39.json
A40: EJ-037 | B40: CP-HU4-16 | C40: 1 | D40: 2026-10-24 00:06 | E40: Node.js fetch (tests/api/ajustes.api.js) | F40: Alvaro Mendoza (QA) | G40: Local: RepresentacionesMartinDB_Pruebas + Edge | H40: 0 registros; ej.: MOVIMIENTO_MERMA por Jorge Luis Paredes Soto el 2026-10-24T05:06:08.750Z — Producto: Tablero Melamina Vesto Roble Cendra 18mm (SKU: 1), Cantidad: 2, Stock Anterior: 95, Stock Nuevo: 93, Doc: AJU-2026-00002 | I40: Fallido | J40: DEF-09 | K40: pruebas/evidencias/pc10/api-2026-10-24T05-06-39.json
...

Sheet Defectos
A1: PC 10 – Registro de defectos
A2: Defectos detectados durante el Sprint 1. "Diferido" = fuera del alcance de HU-004, asignado al Sprint 2.
A3: ID | B3: Título | C3: Descripción | D3: Pasos para reproducir | E3: Resultado esperado | F3: Resultado obtenido | G3: Severidad | H3: Prioridad | I3: Detectado por | J3: Caso relacionado | K3: Fecha detección | L3: Corrección | M3: Fecha corrección | N3: Responsable (propuesto) | O3: Estado
A4: DEF-01 | B4: El folio del ajuste podía repetirse y violar la restricción UNIQUE | C4: sp_AjusteInventarioManual generaba el folio como AJU-fechaHoraMinuto-IdProducto; dos ajustes del mismo producto en el mismo minuto chocaban con la restricción UNIQUE de NumeroAjuste. | D4: Registrar dos mermas del mismo producto dentro del mismo minuto. | E4: Ambos ajustes se registran con folios distintos. | F4: El segundo ajuste fallaba con error de clave duplicada. | G4: Media | H4: Alta | I4: Revisión estática del procedimiento (PC 5) | J4: CP-HU4-05 | K4: 2026-10-23 | L4: Folio AJU-AAAA-NNNNN derivado del IdAjuste (commit 021c96a) | M4: 2026-10-23 | N4: Kevin Llacchua | O4: Cerrado
A5: DEF-02 | B5: El ajuste no se guardaba en la base de datos | C5: El registro de la merma (folio, motivo, justificación, responsable) solo se guardaba en el navegador (localStorage); en SQL Server solo llegaba el movimiento de stock. | D5: Registrar una merma y consultar la tabla AjustesInventario. | E5: El ajuste queda guardado en AjustesInventario. | F5: La tabla no contenía el ajuste; el historial se perdía al cambiar de navegador. | G5: Alta | H5: Alta | I5: Análisis de la HU-004 (PC 5) | J5: CP-HU4-01, CP-HU4-14 | K5: 2026-10-23 | L5: API POST /api/ajustes + sp_AjusteInventarioManual y pantalla conectada (commits 021c96a, f14c9c5) | M5: 2026-10-23 | N5: Kevin Llacchua | O5: Cerrado
A6: DEF-03 | B6: La justificación técnica no era obligatoria fuera de la pantalla | C6: Solo el formulario exigía la justificación; el controlador y los datos aceptaban ajustes sin ella, incumpliendo HU-004 CA-1. | D6: Enviar un ajuste sin justificación sin pasar por el formulario. | E6: Se rechaza el ajuste. | F6: Se aceptaba el ajuste sin justificación. | G6: Media | H6: Alta | I6: Análisis de la HU-004 (PC 5) | J6: CP-HU4-02, CP-HU4-06, CP-HU4-07 | K6: 2026-10-23 | L6: Validación en servidor (adjustmentRules.js), en el procedimiento y en AdjustmentModel (commits 021c96a, f14c9c5) | M6: 2026-10-23 | N6: Kevin Llacchua | O6: Cerrado
A7: DEF-04 | B7: ProductModel.validate aceptaba valores no numéricos | C7: Number("abc") es NaN y toda comparación con NaN es falsa, por lo que precio, costo y stocks no numéricos pasaban la validación. | D7: Validar un producto con precioVenta = "abc". | E7: Validación rechazada. | F7: isValid = true. | G7: Media | H7: Media | I7: Prueba unitaria CP-UT-04 (ciclo 1) | J7: CP-UT-04 | K7: 2026-10-23 | L7: Validación con Number.isFinite / Number.isInteger (commit ff54c55) | M7: 2026-10-23 | N7: Kevin Llacchua | O7: Cerrado
A8: DEF-05 | B8: MovementModel aceptaba cantidades decimales | C8: El mensaje exige "número entero" pero se aceptaba 2.5 planchas. | D8: Validar una salida de 2.5 unidades. | E8: Validación rechazada. | F8: isValid = true. | G8: Media | H8: Media | I8: Prueba unitaria CP-UT-03 (ciclo 1) | J8: CP-UT-03 | K8: 2026-10-23 | L8: Number.isInteger (commit ff54c55) | M8: 2026-10-23 | N8: Kevin Llacchua | O8: Cerrado
A9: DEF-06 | B9: MovementModel aceptaba tipos de movimiento desconocidos | C9: Un tipo como TRASLADO pasaba la validación y createMovementRecord restaba la cantidad del stock. | D9: Validar un movimiento de tipo TRASLADO con cantidad 50. | E9: Validación rechazada. | F9: isValid = true (y luego se descontaba el stock). | G9: Media | H9: Media | I9: Prueba unitaria CP-UT-03 (ciclo 1) | J9: CP-UT-03 | K9: 2026-10-23 | L9: Error "Tipo de movimiento no reconocido." (commit ff54c55) | M9: 2026-10-23 | N9: Kevin Llacchua | O9: Cerrado
A10: DEF-07 | B10: El subtotal de las órdenes de compra no se redondeaba | C10: Errores de coma flotante en importes (3 × 0.10 = 0.30000000000000004). | D10: Calcular los totales de 3 unidades a S/ 0.10. | E10: Subtotal 0.30. | F10: Subtotal 0.30000000000000004. | G10: Baja | H10: Baja | I10: Prueba unitaria CP-UT-05 (ciclo 1) | J10: CP-UT-05 | K10: 2026-10-23 | L10: Redondeo a céntimos (commit ff54c55) | M10: 2026-10-23 | N10: Kevin Llacchua | O10: Cerrado
A11: DEF-08 | B11: Las fechas se mostraban con 5 horas de desfase (SQL Server local) | C11: SYSDATETIME() guarda la hora local de Lima, pero el driver mssql la interpretaba como UTC y el navegador restaba 5 horas. | D11: Registrar un ajuste a las 00:01 del 24/10 y ver el historial. | E11: Fecha 24/10/2026 00:01. | F11: Fecha 23/10/2026 19:01 (ver evidencia de CPF-01, ciclo 1). | G11: Media | H11: Media | I11: Revisión de la evidencia de Selenium CP-HU4-01 (ciclo 1) | J11: CP-HU4-01 | K11: 2026-10-24 | L11: Opción DB_USE_UTC=false para SQL Server local (commit afb2f9b) | M11: 2026-10-24 | N11: Kevin Llacchua | O11: Cerrado
A12: DEF-09 | B12: La bitácora no registraba el motivo ni el SKU real | C12: sp_RegistrarMovimiento escribía el IdProducto con la etiqueta "SKU" y no incluía el motivo del ajuste, incumpliendo HU-004 CA-2. | D12: Registrar un ajuste y consultar BitacoraAuditoria. | E12: Descripción con SKU real, cantidad y motivo. | F12: "(SKU: 1)" y sin motivo (ver api-2026-10-24T05-06-39.json). | G12: Media | H12: Alta | I12: Prueba de API CP-HU4-16 (ciclo 1) | J12: CP-HU4-16 | K12: 2026-10-24 | L12: Descripción con CodigoSKU y observación (commit b4e05f0) | M12: 2026-10-24 | N12: Kevin Llacchua | O12: Cerrado
A13: DEF-10 | B13: Ambiente local: SQL Server sin TCP/IP, solo acepta 1 conexión | C13: El proyecto se conectaba al puerto 1434, que es la conexión de administrador dedicada (DAC): admite una sola conexión y solo a usuarios sysadmin. Con la web abierta, las conexiones simultáneas se cortaban (ECONNRESET). | D13: Abrir la web con la API local y navegar (varias peticiones simultáneas). | E13: Todas las peticiones responden. | F13: Error 500 y "Connection lost - read ECONNRESET". | G13: Alta | H13: Alta | I13: Verificación manual de la PC 6 | J13: CP-HU4-01 a CP-HU4-16 (ciclo 3) | K13: 2026-10-23 | L13: TCP/IP habilitado en MSSQLSERVER (puerto 1433); configuración y plantillas con DB_PORT=1433 y sin DB_POOL_MAX (commit ac88fe7). Recomendado además: usuario de BD local sin rol sysadmin. | M13: 2026-10-25 | N13: Kevin Llacchua | O13: Cerrado
A14: DEF-11 | B14: El Kardex no calcula el costo promedio ponderado | C14: sp_RegistrarMovimiento y el frontend guardan como "costo promedio" el costo del último movimiento, no el promedio ponderado que exige HU-005. | D14: Registrar dos entradas con costos distintos y revisar el Kardex. | E14: Costo promedio ponderado de las existencias. | F14: Costo unitario del último movimiento. | G14: Alta | H14: Media | I14: Revisión de código durante PC 5 | J14: — (HU-005, Sprint 2) | K14: 2026-10-23 | L14: Diferido al Sprint 2 (HU-005). | N14: Kevin Llacchua | O14: Diferido
A15: DEF-12 | B15: HU-005 sin filtro por fechas ni exportación a Excel/PDF | C15: La vista de Kardex exporta CSV e imprime, pero no filtra por rango de fechas ni exporta Excel/PDF como pide HU-005. | D15: Abrir Kardex y buscar el filtro de fechas. | E15: Filtro por rango y exportación Excel/PDF. | F15: No existe el filtro; solo CSV e impresión. | G15: Media | H15: Media | I15: Revisión de HU vs. aplicación | J15: — (HU-005, Sprint 2) | K15: 2026-10-23 | L15: Diferido al Sprint 2 (HU-005). | N15: Kevin Llacchua | O15: Diferido
A16: DEF-13 | B16: HU-003 no impide asignar mercadería a un rack con sobrepeso | C16: La vista de racks marca el sobrepeso en pantalla, pero no bloquea la asignación como exige HU-003. | D16: Asignar a un rack un lote que supere su capacidad en kg. | E16: Asignación denegada con alerta. | F16: Solo se resalta; no hay bloqueo. | G16: Media | H16: Media | I16: Revisión de HU vs. aplicación | J16: — (HU-003, Sprint 2) | K16: 2026-10-23 | L16: Diferido al Sprint 2 (HU-003). | N16: Kevin Llacchua | O16: Diferido
A17: DEF-14 | B17: HU-002: crear, editar y dar de baja productos no se guarda en la base | C17: Las operaciones del catálogo se guardan solo en el navegador; la API solo expone la consulta de productos. | D17: Crear un producto y consultar la tabla Productos. | E17: El producto queda en SQL Server. | F17: Solo existe en el navegador. | G17: Alta | H17: Alta | I17: Revisión de HU vs. aplicación | J17: — (HU-002, Sprint 2) | K17: 2026-10-23 | L17: Diferido al Sprint 2 (HU-002). | N17: Kevin Llacchua | O17: Diferido

Sheet Resumen
A1: Resumen de calidad – Sprint 1 (HU-004)
A2: Fórmulas sobre las hojas Casos de Prueba, Ejecución y Defectos.
A4: Casos de prueba (PC 9) | B4: Total
A5: Casos diseñados | B5: =COUNTA('Casos de Prueba'!$A$4:$A$25) -> 22
A6: Prioridad Alta | B6: =COUNTIF('Casos de Prueba'!$F$4:$F$25,"Alta") -> 12
A7: Prioridad Media | B7: =COUNTIF('Casos de Prueba'!$F$4:$F$25,"Media") -> 9
A8: Prioridad Baja | B8: =COUNTIF('Casos de Prueba'!$F$4:$F$25,"Baja") -> 1
A9: Tipo Funcional E2E | B9: =COUNTIF('Casos de Prueba'!$D$4:$D$25,"Funcional E2E") -> 3
A10: Tipo API | B10: =COUNTIF('Casos de Prueba'!$D$4:$D$25,"API") -> 13
A11: Tipo Unitaria | B11: =COUNTIF('Casos de Prueba'!$D$4:$D$25,"Unitaria") -> 6
A13: Ejecución (PC 10) | B13: Ciclo 1 | C13: Ciclo 2 | D13: Ciclo 3 | E13: Total
A14: Ejecuciones | B14: =COUNTIF('Ejecución'!$C$4:$C$66,1) -> 22 | C14: =COUNTIF('Ejecución'!$C$4:$C$66,2) -> 25 | D14: =COUNTIF('Ejecución'!$C$4:$C$66,3) -> 16 | E14: =COUNTA('Ejecución'!$A$4:$A$66) -> 63
A15: Aprobadas | B15: =COUNTIFS('Ejecución'!$C$4:$C$66,1,'Ejecución'!$I$4:$I$66,"Aprobado") -> 18 | C15: =COUNTIFS('Ejecución'!$C$4:$C$66,2,'Ejecución'!$I$4:$I$66,"Aprobado") -> 25 | D15: =COUNTIFS('Ejecución'!$C$4:$C$66,3,'Ejecución'!$I$4:$I$66,"Aprobado") -> 16 | E15: =COUNTIF('Ejecución'!$I$4:$I$66,"Aprobado") -> 59
A16: Fallidas | B16: =COUNTIFS('Ejecución'!$C$4:$C$66,1,'Ejecución'!$I$4:$I$66,"Fallido") -> 4 | C16: =COUNTIFS('Ejecución'!$C$4:$C$66,2,'Ejecución'!$I$4:$I$66,"Fallido") -> 0 | D16: =COUNTIFS('Ejecución'!$C$4:$C$66,3,'Ejecución'!$I$4:$I$66,"Fallido") -> 0 | E16: =COUNTIF('Ejecución'!$I$4:$I$66,"Fallido") -> 4
A17: Bloqueadas | B17: =COUNTIFS('Ejecución'!$C$4:$C$66,1,'Ejecución'!$I$4:$I$66,"Bloqueado") -> 0 | C17: =COUNTIFS('Ejecución'!$C$4:$C$66,2,'Ejecución'!$I$4:$I$66,"Bloqueado") -> 0 | D17: =COUNTIFS('Ejecución'!$C$4:$C$66,3,'Ejecución'!$I$4:$I$66,"Bloqueado") -> 0 | E17: =COUNTIF('Ejecución'!$I$4:$I$66,"Bloqueado") -> 0
A18: % de aprobación | B18: =IFERROR(B15/B14,0) -> 0.81818182 | C18: =IFERROR(C15/C14,0) -> 1 | D18: =IFERROR(D15/D14,0) -> 1 | E18: =IFERROR(E15/E14,0) -> 0.93650794 | F18: Ciclo 2 = regresión tras corregir defectos · Ciclo 3 = verificación de DEF-10
A20: Defectos (PC 10) | B20: Total
A21: Defectos registrados | B21: =COUNTA('Defectos'!$A$4:$A$17) -> 14
A22: Severidad Alta | B22: =COUNTIF('Defectos'!$G$4:$G$17,"Alta") -> 4
A23: Severidad Media | B23: =COUNTIF('Defectos'!$G$4:$G$17,"Media") -> 9
A24: Severidad Baja | B24: =COUNTIF('Defectos'!$G$4:$G$17,"Baja") -> 1
A25: Estado Cerrado | B25: =COUNTIF('Defectos'!$O$4:$O$17,"Cerrado") -> 10
A26: Estado Abierto | B26: =COUNTIF('Defectos'!$O$4:$O$17,"Abierto") -> 0
A27: Estado Diferido | B27: =COUNTIF('Defectos'!$O$4:$O$17,"Diferido") -> 4
A29: Cobertura de pruebas unitarias (PC 7) | B29: Obtenido | C29: Mínimo | D29: Cumple
A30: Cobertura de líneas (%) | B30: 93.38 | C30: 80 | D30: =IF(B30>=C30,"Sí","No") -> Sí | F30: Fuente: pruebas/evidencias/pc07/vitest-ejecucion-2-cobertura.txt (umbral en vitest.config.js)
A31: Cobertura de ramas (%) | B31: 96.29 | C31: 75 | D31: =IF(B31>=C31,"Sí","No") -> Sí | F31: Fuente: pruebas/evidencias/pc07/vitest-ejecucion-2-cobertura.txt (umbral en vitest.config.js)
A32: Cobertura de funciones (%) | B32: 95.23 | C32: 80 | D32: =IF(B32>=C32,"Sí","No") -> Sí | F32: Fuente: pruebas/evidencias/pc07/vitest-ejecucion-2-cobertura.txt (umbral en vitest.config.js)
A33: Cobertura de sentencias (%) | B33: 93.38 | C33: 80 | D33: =IF(B33>=C33,"Sí","No") -> Sí | F33: Fuente: pruebas/evidencias/pc07/vitest-ejecucion-2-cobertura.txt (umbral en vitest.config.js)
